<?xml version="1.0"?>
<robot name="tortoisebot">

    <!--台座のモデル-->
    <link name="base_link">
        <!--外観-->
        <visual>
            <geometry>
                <box size="0.6 0.3 0.3"/>
            </geometry>
            <material name="silver">
                <color rgba="0.75 0.75 0.75 1"/>
            </material>
        </visual>
        <!--物理的特性-->
        <!--干渉-->
        <collision>
          <geometry>
            <box size="0.6 0.3 0.3"/>
          </geometry>
        </collision>
        <!--慣性-->
        <inertial>
          <mass value="1.0"/>
          <inertia ixx="0.015" iyy="0.0375" izz="0.0375" ixy="0" ixz="0" iyz="0"/>
        </inertial>
    </link>

    <!--キャスターのモデル-->
    <link name="front_caster">
        <!--外観-->
        <visual>
            <geometry>
                <box size="0.1 0.1 0.3"/>
            </geometry>
            <material name="silver"/>
        </visual>
        <!--物理的特性-->
        <!--干渉-->
        <collision>
          <geometry>
            <box size="0.1 0.1 0.3"/>
          </geometry>
        </collision>
        <!--慣性-->
        <inertial>
          <mass value="0.1"/>
          <inertia ixx="0.00083" iyy="0.00083" izz="0.000167" ixy="0" ixz="0" iyz="0"/>
        </inertial>
    </link>
    <!--台座とキャスターをつなぐ関節-->
    <joint name="front_caster_joint" type="continuous">
        <axis xyz="0 0 1"/>
        <parent link="base_link"/>
        <child link="front_caster"/>
        <origin rpy="0 0 0" xyz="0.3 0 0"/>
    </joint>

    <!--前輪のモデル-->
    <link name="front_wheel">
        <visual>
            <geometry>
                <cylinder length="0.05" radius="0.035"/>
            </geometry>
            <material name="black"/>
        </visual>
        <!--物理的特性-->
        <!--干渉-->
        <collision>
          <geometry>
            <cylinder length="0.05" radius="0.035"/>
          </geometry>
        </collision>
        <!--慣性-->
        <inertial>
          <mass value="0.1"/>
          <inertia ixx="5.1458e-5" iyy="5.1458e-5" izz="6.125e-5" ixy="0" ixz="0" iyz="0"/>
        </inertial>
    </link>
    <!--前輪とキャスターをつなぐ関節-->
    <joint name="front_wheel_joint" type="continuous">
        <axis xyz="0 0 1"/>
        <parent link="front_caster"/>
        <child link="front_wheel"/>
        <origin rpy="-1.5708 0 0" xyz="0.05 0 -.15"/>
    </joint>

    <!--右後方車輪のモデル-->
    <link name="right_wheel">
        <visual>
            <geometry>
                <cylinder length="0.05" radius="0.035"/>
            </geometry>
            <material name="black">
                <color rgba="0 0 0 1"/>
            </material>
        </visual>
        <!--物理的特性-->
        <!--干渉-->
        <collision>
          <geometry>
            <cylinder length="0.05" radius="0.035"/>
          </geometry>
        </collision>
        <!--慣性-->
        <inertial>
          <mass value="0.1"/>
          <inertia ixx="5.1458e-5" iyy="5.1458e-5" izz="6.125e-5" ixy="0" ixz="0" iyz="0"/>
        </inertial>
    </link>
    <!--右後方車輪と台車をつなぐ関節-->
    <joint name="right_wheel_joint" type="continuous">
        <axis xyz="0 0 1"/>
        <parent link="base_link"/>
        <child link="right_wheel"/>
        <origin rpy="-1.5708 0 0" xyz="-0.2825 -0.125 -.15"/>
    </joint>

    <!--左後方車輪のモデル-->
    <link name="left_wheel">
        <visual>
            <geometry>
                <cylinder length="0.05" radius="0.035"/>
            </geometry>
            <material name="black"/>
        </visual>
        <!--物理的特性-->
        <!--干渉-->
        <collision>
          <geometry>
            <cylinder length="0.05" radius="0.035"/>
          </geometry>
        </collision>
        <!--慣性-->
        <inertial>
          <mass value="0.1"/>
          <inertia ixx="5.1458e-5" iyy="5.1458e-5" izz="6.125e-5" ixy="0" ixz="0" iyz="0"/>
        </inertial>
    </link>
    <!--左後方車輪と台車をつなぐ関節-->
    <joint name="left_wheel_joint" type="continuous">
        <axis xyz="0 0 1"/>
        <parent link="base_link"/>
        <child link="left_wheel"/>
        <origin rpy="-1.5708 0 0" xyz="-0.2825 0.125 -.15"/>
    </joint>


    <!--センサ搭載の設定-->
    <link name="hokuyo_link">
      <!--可視化-->
      <visual>
        <origin xyz="0 0 0" rpy="0 0 0"/>
        <geometry>
          <box size="0.1 0.1 0.1"/>
        </geometry>
      </visual>
      <!--物理的特性-->
      <!--干渉-->
      <collision>
        <origin xyz="0 0 0" rpy="0 0 0"/>
        <geometry>
          <box size="0.1 0.1 0.1"/>
        </geometry>
      </collision>
      <!--慣性-->
      <inertial>
        <mass value="1e-5"/>
        <origin xyz="0 0 0" rpy="0 0 0"/>
        <inertia ixx="1e-6" ixy="0" ixz="0" iyy="1e-6" iyz="0" izz="1e-6"/>
      </inertial>
    </link>
    <!--センサと台車をつなぐ関節-->
    <joint name="hokuyo_joint" type="fixed">
      <axis xyz="0 1 0"/>
      <origin xyz="0 0 0.2" rpy="0 0 0"/>
      <parent link="base_link"/>
      <child link="hokuyo_link"/>
    </joint>



<!--機能的な部分をロードするための追加要素-->
  <gazebo>
    <!--差動駆動プラグインを指定-->
    <plugin name="differential_drive_controller" filename="libgazebo_ros_diff_drive.so">
      <!--left_wheel_jointとright_wheel_jointをそれぞれ左関節右関節に指定-->
      <leftJoint>left_wheel_joint</leftJoint>
      <rightJoint>right_wheel_joint</rightJoint>
      <!--台座であるbase_linkをrobotBaseFrameに指定-->
      <robotBaseFrame>base_link</robotBaseFrame>
      <!--トレッドを0.25m，車輪直径0.07mとする-->
      <wheelSeparation>0.25</wheelSeparation>
      <wheelDiameter>0.07</wheelDiameter>
      <!--車輪の状態を配信する設定にする-->
      <publishWheelJointState>true</publishWheelJointState>
    </plugin>

    <!--関節状態配信プラグインを指定-->
    <plugin name="joint_state_publisher" filename="libgazebo_ros_joint_state_publisher.so">
      <!--対象とする関節名を指定-->
      <jointName>front_caster_joint, front_wheel_joint</jointName>
    </plugin>
  </gazebo>

  <!--レーザセンサを定義する-->
  <gazebo reference="hokuyo_link">
        <sensor type="ray" name="hokuyo">
        <!--sensor type="gpu_ray" name="hokuyo"-->
        <pose>0 0 0 0 0 0 </pose>
        <visualize>false</visualize>
        <update_rate>40</update_rate>
        <ray>
            <scan>
            <horizontal>
                    <samples>720</samples>
                    <resolution>1</resolution>
                    <min_angle>-1.570796</min_angle>
                    <max_angle>1.570796</max_angle>
            </horizontal>
            </scan>
            <range>
                <min>0.10</min>
                <max>30.0</max>
                <resolution>0.01</resolution>
            </range>
            <noise>
            <type>gaussian</type>
            <!-- Noise parameters based on published spec for Hokuyo laser
                achieving "+-30mm" accuracy at range < 10m.  A mean of 0.0m and
                stddev of 0.01m will put 99.7% of samples within 0.03m of the true
                reading. -->
            <mean>0.0</mean>
            <stddev>0.01</stddev>
            </noise>
        </ray>
        <!--レーザセンサのためのプラグインを指定-->
        <plugin name="laser" filename="libgazebo_ros_laser.so">
                <!--plugin name="gpu_laser" filename="libgazebo_ros_gpu_laser.so"-->
                <topicName>/scan</topicName>
                <frameName>hokuyo_link</frameName>
        </plugin>
        </sensor>
  </gazebo>

</robot>
